2021-01-09 11:17:40,604 INFO    MainThread:17212 [wandb_setup.py:_flush():68] setting env: {}
2021-01-09 11:17:40,604 INFO    MainThread:17212 [wandb_setup.py:_flush():68] multiprocessing start_methods=spawn
2021-01-09 11:17:40,605 INFO    MainThread:17212 [wandb_setup.py:_flush():68] setting login settings: {}
2021-01-09 11:17:40,605 INFO    MainThread:17212 [wandb_init.py:_log_setup():301] Logging user logs to wandb\run-20210109_111740-3p5kejj7\logs\debug.log
2021-01-09 11:17:40,605 INFO    MainThread:17212 [wandb_init.py:_log_setup():302] Logging internal logs to wandb\run-20210109_111740-3p5kejj7\logs\debug-internal.log
2021-01-09 11:17:43,056 INFO    MainThread:17212 [wandb_run.py:_console_start():1322] atexit reg
2021-01-09 11:17:43,060 INFO    MainThread:17212 [wandb_run.py:_redirect():1192] redirect: SettingsConsole.WRAP
2021-01-09 11:17:43,060 INFO    MainThread:17212 [wandb_run.py:_redirect():1223] Wrapping output streams.
2021-01-09 11:17:43,061 INFO    MainThread:17212 [wandb_run.py:_redirect():1239] Redirects installed.
2021-01-09 11:17:46,613 INFO    MainThread:17212 [wandb_run.py:_atexit_cleanup():1295] got exitcode: 1
2021-01-09 11:17:46,614 INFO    MainThread:17212 [wandb_run.py:_restore():1267] restore
2021-01-09 11:17:46,625 INFO    MainThread:17212 [wandb_run.py:_wait_for_finish():1409] got exit ret: uuid: "8f463de493fb48898b81704d864a23ab"
response {
  poll_exit_response {
    file_counts {
      wandb_count: 1
    }
    pusher_stats {
      uploaded_bytes: 779
      total_bytes: 779
    }
  }
}

2021-01-09 11:17:48,631 INFO    MainThread:17212 [wandb_run.py:_wait_for_finish():1409] got exit ret: uuid: "f31888e0bc3b4d00b90cf25853733748"
response {
  poll_exit_response {
    done: true
    exit_result {
    }
    file_counts {
      wandb_count: 5
    }
    pusher_stats {
      uploaded_bytes: 3767
      total_bytes: 3767
    }
  }
}

2021-01-09 11:17:49,787 INFO    MainThread:17212 [wandb_run.py:_show_files():1618] logging synced files
2021-01-09 11:17:49,811 INFO    MainThread:17212 [internal.py:handle_exit():138] Internal process exited
